Workbook

Sheet Summary
A1: TechNova IT Helpdesk: Test Report
A3: Project | B3: TechNova IT Helpdesk (Jira space TNH)
A4: Application | B4: Flask + SQLite web app
A5: Build tested first | B5: v1.0
A6: Build after bug fixes | B6: v1.1
A7: Test environment | B7: Chrome browser, deployed site https://samrudhi.pythonanywhere.com
A8: Jira stories covered | B8: TNH-5, TNH-7, TNH-11, TNH-12, TNH-13
A9: Jira test subtasks | B9: TNH-15 Functional (Black-Box), TNH-16 BVA & ECP (Black-Box), TNH-17 Unit (White-Box), TNH-18 Integration, TNH-19 Bug Fix & Retest
A10: Tester | B10: SAMRUDHI MADANKAR
A11: Date | B11: 25th October 2026
A13: Black-box results by module
A14: Module (Jira) | B14: Total cases | C14: Pass v1.0 | D14: Fail v1.0 | E14: Pass v1.1 (retest) | F14: Fail v1.1 | G14: Pass % v1.1
A15: TNH-5 Registration & Login | B15: =COUNTIF('Black-Box Test Cases'!$B:$B,"TNH-5") -> 18 | C15: =COUNTIFS('Black-Box Test Cases'!$B:$B,"TNH-5",'Black-Box Test Cases'!$K:$K,"Pass") -> 18 | D15: =COUNTIFS('Black-Box Test Cases'!$B:$B,"TNH-5",'Black-Box Test Cases'!$K:$K,"Fail") -> 0 | E15: =COUNTIFS('Black-Box Test Cases'!$B:$B,"TNH-5",'Black-Box Test Cases'!$M:$M,"Pass") -> 18 | F15: =COUNTIFS('Black-Box Test Cases'!$B:$B,"TNH-5",'Black-Box Test Cases'!$M:$M,"Fail") -> 0 | G15: =IF(B15=0,0,E15/B15) -> 1
A16: TNH-7 Profile & Logout | B16: =COUNTIF('Black-Box Test Cases'!$B:$B,"TNH-7") -> 6 | C16: =COUNTIFS('Black-Box Test Cases'!$B:$B,"TNH-7",'Black-Box Test Cases'!$K:$K,"Pass") -> 5 | D16: =COUNTIFS('Black-Box Test Cases'!$B:$B,"TNH-7",'Black-Box Test Cases'!$K:$K,"Fail") -> 1 | E16: =COUNTIFS('Black-Box Test Cases'!$B:$B,"TNH-7",'Black-Box Test Cases'!$M:$M,"Pass") -> 6 | F16: =COUNTIFS('Black-Box Test Cases'!$B:$B,"TNH-7",'Black-Box Test Cases'!$M:$M,"Fail") -> 0 | G16: =IF(B16=0,0,E16/B16) -> 1
A17: TNH-11 Create & View / Search | B17: =COUNTIF('Black-Box Test Cases'!$B:$B,"TNH-11") -> 16 | C17: =COUNTIFS('Black-Box Test Cases'!$B:$B,"TNH-11",'Black-Box Test Cases'!$K:$K,"Pass") -> 14 | D17: =COUNTIFS('Black-Box Test Cases'!$B:$B,"TNH-11",'Black-Box Test Cases'!$K:$K,"Fail") -> 2 | E17: =COUNTIFS('Black-Box Test Cases'!$B:$B,"TNH-11",'Black-Box Test Cases'!$M:$M,"Pass") -> 16 | F17: =COUNTIFS('Black-Box Test Cases'!$B:$B,"TNH-11",'Black-Box Test Cases'!$M:$M,"Fail") -> 0 | G17: =IF(B17=0,0,E17/B17) -> 1
A18: TNH-12 Assign & Update | B18: =COUNTIF('Black-Box Test Cases'!$B:$B,"TNH-12") -> 7 | C18: =COUNTIFS('Black-Box Test Cases'!$B:$B,"TNH-12",'Black-Box Test Cases'!$K:$K,"Pass") -> 7 | D18: =COUNTIFS('Black-Box Test Cases'!$B:$B,"TNH-12",'Black-Box Test Cases'!$K:$K,"Fail") -> 0 | E18: =COUNTIFS('Black-Box Test Cases'!$B:$B,"TNH-12",'Black-Box Test Cases'!$M:$M,"Pass") -> 7 | F18: =COUNTIFS('Black-Box Test Cases'!$B:$B,"TNH-12",'Black-Box Test Cases'!$M:$M,"Fail") -> 0 | G18: =IF(B18=0,0,E18/B18) -> 1
A19: TNH-13 Resolve & Close | B19: =COUNTIF('Black-Box Test Cases'!$B:$B,"TNH-13") -> 6 | C19: =COUNTIFS('Black-Box Test Cases'!$B:$B,"TNH-13",'Black-Box Test Cases'!$K:$K,"Pass") -> 5 | D19: =COUNTIFS('Black-Box Test Cases'!$B:$B,"TNH-13",'Black-Box Test Cases'!$K:$K,"Fail") -> 1 | E19: =COUNTIFS('Black-Box Test Cases'!$B:$B,"TNH-13",'Black-Box Test Cases'!$M:$M,"Pass") -> 6 | F19: =COUNTIFS('Black-Box Test Cases'!$B:$B,"TNH-13",'Black-Box Test Cases'!$M:$M,"Fail") -> 0 | G19: =IF(B19=0,0,E19/B19) -> 1
A20: TOTAL | B20: =SUM(B15:B19) -> 53 | C20: =SUM(C15:C19) -> 49 | D20: =SUM(D15:D19) -> 4 | E20: =SUM(E15:E19) -> 53 | F20: =SUM(F15:F19) -> 0 | G20: =IF(B20=0,0,E20/B20) -> 1
A23: Automated tests (pytest)
A24: Total automated tests | B24: =COUNTA('Automated Tests'!A:A)-1 -> 120
A25: Unit tests (white-box) | B25: =COUNTIF('Automated Tests'!C:C,"Unit (white-box)") -> 73
A26: Integration tests | B26: =COUNTIF('Automated Tests'!C:C,"Integration") -> 39
A27: Bug regression tests | B27: =COUNTIF('Automated Tests'!C:C,"Regression") -> 8
A28: Passed | B28: =COUNTIF('Automated Tests'!E:E,"Pass") -> 120
A29: Statement coverage | B29: 96% app.py, 100% validators.py / workflow.py / db.py, 97% overall (branch coverage on)
A31: Defects
A32: Bugs found | B32: =COUNTA('Bug Report'!A:A)-1 -> 4
A33: Bugs fixed and retested | B33: =COUNTIF('Bug Report'!N:N,"Closed") -> 4
A34: Medium severity | B34: =COUNTIF('Bug Report'!E:E,"Medium") -> 2
A35: Low severity | B35: =COUNTIF('Bug Report'!E:E,"Low") -> 2

Sheet Black-Box Test Cases
A1: TC ID | B1: Jira Story | C1: Module | D1: Test Scenario | E1: Technique | F1: Pre-condition | G1: Test Steps | H1: Test Data | I1: Expected Result | J1: Actual Result (v1.0) | K1: Status (v1.0) | L1: Actual Result (v1.1 retest) | M1: Final Status | N1: Bug ID
A2: TC-01 | B2: TNH-5 | C2: Registration | D2: Register with all valid details | E2: ECP (valid class) | F2: User not logged in | G2: 1. Open /register 2. Fill all fields 3. Click Register | H2: Name: Riya Sharma, Email: riya@technova.com, Pwd: Riya1234 | I2: Account created message, redirected to Login page | J2: Account created. You can log in now. (page: /login) | K2: Pass | L2: Same as v1.0 | M2: Pass
A3: TC-02 | B3: TNH-5 | C3: Registration | D3: Register with an email that already exists | E3: ECP (invalid class) | F3: noah@technova.com already registered | G3: 1. Open /register 2. Use existing email 3. Click Register | H3: Email: noah@technova.com | I3: Error: An account with this email already exists | J3: An account with this email already exists. | K3: Pass | L3: Same as v1.0 | M3: Pass
A4: TC-03 | B4: TNH-5 | C4: Registration | D4: Password and Confirm Password do not match | E4: ECP (invalid class) | F4: User not logged in | G4: 1. Open /register 2. Enter different confirm password 3. Click Register | H4: Pwd: Riya1234, Confirm: Riya4321 | I4: Error: Passwords do not match | J4: Passwords do not match. | K4: Pass | L4: Same as v1.0 | M4: Pass
A5: TC-04 | B5: TNH-5 | C5: Registration | D5: Name with 1 character (min - 1) | E5: BVA | F5: User not logged in | G5: 1. Open /register 2. Enter 1-letter name 3. Click Register | H5: Name: A | I5: Error: Name must be 2 to 50 characters | J5: Name must be 2 to 50 characters. | K5: Pass | L5: Same as v1.0 | M5: Pass
A6: TC-05 | B6: TNH-5 | C6: Registration | D6: Name with 2 characters (min) | E6: BVA | F6: User not logged in | G6: 1. Open /register 2. Enter 2-letter name 3. Click Register | H6: Name: Al | I6: Account created | J6: Account created. You can log in now. | K6: Pass | L6: Same as v1.0 | M6: Pass
A7: TC-06 | B7: TNH-5 | C7: Registration | D7: Password with 7 characters (min - 1) | E7: BVA | F7: User not logged in | G7: 1. Open /register 2. Enter 7-char password 3. Click Register | H7: Pwd: abcde12 | I7: Error: Password must be at least 8 characters | J7: Password must be at least 8 characters. | K7: Pass | L7: Same as v1.0 | M7: Pass
A8: TC-07 | B8: TNH-5 | C8: Registration | D8: Password with exactly 8 characters (min) | E8: BVA | F8: User not logged in | G8: 1. Open /register 2. Enter 8-char password 3. Click Register | H8: Pwd: abcdef12, Email: tester@technova.com | I8: Account created | J8: Account created. You can log in now. | K8: Pass | L8: Same as v1.0 | M8: Pass
A9: TC-08 | B9: TNH-5 | C9: Registration | D9: Password with exactly 20 characters (max) | E9: BVA | F9: User not logged in | G9: 1. Open /register 2. Enter 20-char password 3. Click Register | H9: Pwd: abcdefghij123456789x | I9: Account created | J9: Account created. You can log in now. | K9: Pass | L9: Same as v1.0 | M9: Pass
A10: TC-09 | B10: TNH-5 | C10: Registration | D10: Password with 21 characters (max + 1) | E10: BVA | F10: User not logged in | G10: 1. Open /register 2. Enter 21-char password 3. Click Register | H10: Pwd: abcdefghij123456789xy | I10: Error: Password must be at most 20 characters | J10: Password must be at most 20 characters. | K10: Pass | L10: Same as v1.0 | M10: Pass
A11: TC-10 | B11: TNH-5 | C11: Registration | D11: Password with digits only | E11: ECP (invalid class) | F11: User not logged in | G11: 1. Open /register 2. Enter numeric password 3. Click Register | H11: Pwd: 12345678 | I11: Error: Password must contain at least one letter | J11: Password must contain at least one letter. | K11: Pass | L11: Same as v1.0 | M11: Pass
A12: TC-11 | B12: TNH-5 | C12: Registration | D12: Invalid email format (no @) | E12: ECP (invalid class) | F12: User not logged in | G12: 1. Open /register 2. Enter email without @ 3. Click Register | H12: Email: riyatechnova.com | I12: Error: Enter a valid email address | J12: Enter a valid email address. | K12: Pass | L12: Same as v1.0 | M12: Pass
A13: TC-12 | B13: TNH-5 | C13: Registration | D13: Submit registration with all fields empty | E13: ECP (invalid class) | F13: User not logged in | G13: 1. Open /register 2. Leave everything blank 3. Click Register | H13: (blank) | I13: Errors: Name is required, Email is required, Password is required | J13: Name is required. | Email is required. | Password is required. | K13: Pass | L13: Same as v1.0 | M13: Pass
... A24: TC-23 | B24: TNH-7 | C24: Logout | D24: Logout and try to go back to dashboard | E24: Use case / security | F24: Logged in | G24: 1. Click Logout 2. Open /dashboard | H24: - | I24: Logged out message; /dashboard redirects to Login | J24: You have been logged out.; /dashboard -> /login?next=/dashboard | K24: Pass | L24: Same as v1.0 | M24: Pass
A25: TC-24 | B25: TNH-7 | C25: Profile | D25: Department with 5000 characters | E25: BVA (way above max) | F25: Logged in | G25: 1. Open Profile 2. Paste 5000 chars in Department 3. Click Save | H25: Department: 'x' * 5000 | I25: Error: Department must be at most 50 characters | J25: Profile updated. | K25: Fail | L25: Department must be at most 50 characters. | M25: Pass | N25: BUG-04
A26: TC-25 | B26: TNH-11 | C26: Create Ticket | D26: Create ticket with valid details | E26: ECP (valid class) | F26: Logged in as Noah (employee) | G26: 1. Click + New Ticket 2. Fill form 3. Click Submit | H26: Title: Outlook not syncing, Desc: Emails stopped syncing since morning, Software, High | I26: TKT-0004 created, status Open, Unassigned | J26: Ticket TKT-0004 created.; status=Open; assignee=Unassigned | K26: Pass | L26: Same as v1.0 | M26: Pass
A27: TC-26 | B27: TNH-11 | C27: Create Ticket | D27: Title with 4 characters (min - 1) | E27: BVA | F27: Logged in | G27: 1. New Ticket 2. Enter 4-char title 3. Submit | H27: Title: abcd | I27: Error: Title must be at least 5 characters | J27: Title must be at least 5 characters. | K27: Pass | L27: Same as v1.0 | M27: Pass
A28: TC-27 | B28: TNH-11 | C28: Create Ticket | D28: Title with 5 characters (min) | E28: BVA | F28: Logged in | G28: 1. New Ticket 2. Enter 5-char title 3. Submit | H28: Title: Mouse | I28: Ticket created | J28: Ticket TKT-0005 created. | K28: Pass | L28: Same as v1.0 | M28: Pass
A29: TC-28 | B29: TNH-11 | C29: Create Ticket | D29: Title with 100 characters (max) | E29: BVA | F29: Logged in | G29: 1. New Ticket 2. Enter 100-char title 3. Submit | H29: Title: 'T' * 100 | I29: Ticket created | J29: Ticket TKT-0006 created. | K29: Pass | L29: Same as v1.0 | M29: Pass
A30: TC-29 | B30: TNH-11 | C30: Create Ticket | D30: Title with 101 characters (max + 1) | E30: BVA | F30: Logged in | G30: 1. New Ticket 2. Enter 101-char title 3. Submit | H30: Title: 'T' * 101 | I30: Error: Title must be at most 100 characters | J30: Title must be at most 100 characters. | K30: Pass | L30: Same as v1.0 | M30: Pass
A31: TC-30 | B31: TNH-11 | C31: Create Ticket | D31: Description with 9 characters (min - 1) | E31: BVA | F31: Logged in | G31: 1. New Ticket 2. Enter 9-char description 3. Submit | H31: Desc: 123456789 | I31: Error: Description must be at least 10 characters | J31: Description must be at least 10 characters. | K31: Pass | L31: Same as v1.0 | M31: Pass
A32: TC-31 | B32: TNH-11 | C32: Create Ticket | D32: Description with 10 characters (min) | E32: BVA | F32: Logged in | G32: 1. New Ticket 2. Enter 10-char description 3. Submit | H32: Desc: Keys stuck | I32: Ticket created | J32: Ticket TKT-0007 created. | K32: Pass | L32: Same as v1.0 | M32: Pass
A33: TC-32 | B33: TNH-11 | C33: Create Ticket | D33: Submit without category and priority | E33: ECP (invalid class) | F33: Logged in | G33: 1. New Ticket 2. Fill title + description only 3. Submit | H33: Category/Priority: not selected | I33: Errors: Select a valid category, Select a valid priority | J33: Select a valid category. | Select a valid priority. | K33: Pass | L33: Same as v1.0 | M33: Pass
A34: TC-33 | B34: TNH-11 | C34: View Tickets | D34: Employee sees only their own tickets | E34: Use case / role | F34: Logged in as Swara (owns TKT-0002 only) | G34: 1. Login as Swara 2. Open Tickets | H34: - | I34: Only TKT-0002 is listed | J34: Listed: TKT-0002 | K34: Pass | L34: Same as v1.0 | M34: Pass
A35: TC-34 | B35: TNH-11 | C35: View Tickets | D35: Employee opens another person's ticket by URL | E35: Security / negative | F35: Logged in as Swara | G35: 1. Type /tickets/1 in the address bar | H35: URL: /tickets/1 (Noah's) | I35: 403 - You don't have permission | J35: HTTP 403: 403 You don't have permission to do that. Go home | K35: Pass | L35: Same as v1.0 | M35: Pass
A36: TC-35 | B36: TNH-11 | C36: Search | D36: Search tickets by keyword | E36: ECP (valid class) | F36: Logged in as admin | G36: 1. Tickets page 2. Type keyword 3. Apply | H36: q = vpn | I36: 1 ticket found: VPN keeps disconnecting | J36: 1 found | K36: Pass | L36: Same as v1.0 | M36: Pass
A37: TC-36 | B37: TNH-11 | C37: Search | D37: Search by ticket number | E37: ECP (valid class) | F37: Logged in as admin | G37: 1. Tickets page 2. Type ticket number 3. Apply | H37: q = TKT-0002 | I37: Only TKT-0002 shown | J37: Listed: TKT-0002 | K37: Pass | L37: Same as v1.0 | M37: Pass
A38: TC-37 | B38: TNH-11 | C38: Filter | D38: Filter by Status = Open and Priority = High | E38: Decision table | F38: Logged in as admin | G38: 1. Tickets page 2. Choose Status Open, Priority High 3. Apply | H38: Status: Open, Priority: High | I38: Only Open + High tickets listed (TKT-0001, TKT-0004) | J38: Listed: TKT-0001, TKT-0004 | K38: Pass | L38: Same as v1.0 | M38: Pass
A39: TC-38 | B39: TNH-11 | C39: Search | D39: Search using special character % | E39: ECP (special characters) | F39: Logged in as admin | G39: 1. Tickets page 2. Type % in search 3. Apply | H39: q = % | I39: 0 tickets found (no title contains %) | J39: 7 ticket(s) found | K39: Fail | L39: 0 ticket(s) found | M39: Pass | N39: BUG-01
A40: TC-39 | B40: TNH-11 | C40: Search | D40: Search a number that appears only in a description | E40: ECP (numeric input) | F40: Ticket exists with 'error 404' in description | G40: 1. Create ticket with 404 in description 2. Search 404 | H40: Desc: Intranet page shows error 404; q = 404 | I40: That ticket is found (1 result) | J40: 0 ticket(s) found | K40: Fail | L40: 1 ticket(s) found | M40: Pass | N40: BUG-02
A41: TC-40 | B41: TNH-11 | C41: View Tickets | D41: Open a ticket that does not exist | E41: Negative | F41: Logged in as admin | G41: 1. Open /tickets/999 | H41: URL: /tickets/999 | I41: 404 Page not found | J41: HTTP 404: 404 Page not found. Go home | K41: Pass | L41: Same as v1.0 | M41: Pass
A42: TC-41 | B42: TNH-12 | C42: Assign | D42: Admin assigns a ticket to an agent | E42: Use case flow | F42: TKT-0004 Open and unassigned | G42: 1. Login as admin 2. Open TKT-0004 3. Select Christopher 4. Click Assign | H42: Agent: Christopher | I42: Ticket assigned to Christopher, shown in Assigned to + Activity | J42: Ticket assigned to Christopher.; assignee=Christopher | K42: Pass | L42: Same as v1.0 | M42: Pass
A43: TC-42 | B43: TNH-12 | C43: Assign | D43: Agent cannot see the Assign option | E43: Role based | F43: Logged in as Christopher (agent) | G43: 1. Open TKT-0004 | H43: - | I43: No 'Assign to agent' control | J43: Assign control not shown | K43: Pass | L43: Same as v1.0 | M43: Pass
A44: TC-43 | B44: TNH-12 | C44: Update Status | D44: Start work on a ticket that has no agent | E44: Negative | F44: TKT-0001 Open, unassigned; logged in as admin | G44: 1. Open TKT-0001 2. Click Start work | H44: - | I44: Error: Assign the ticket to an agent first | J44: Assign the ticket to an agent first. | K44: Pass | L44: Same as v1.0 | M44: Pass
A45: TC-44 | B45: TNH-12 | C45: Update Status | D45: Assigned agent starts work | E45: State transition | F45: TKT-0004 assigned to Christopher | G45: 1. Login as Christopher 2. Open TKT-0004 3. Click Start work | H45: - | I45: Status changes Open -> In Progress | J45: Ticket moved to In Progress.; status=In Progress | K45: Pass | L45: Same as v1.0 | M45: Pass
A46: TC-45 | B46: TNH-12 | C46: Update Priority | D46: Agent changes priority | E46: Use case flow | F46: Logged in as Christopher | G46: 1. Open TKT-0004 2. Choose Critical 3. Update priority | H46: Priority: Critical | I46: Priority updated; activity shows High -> Critical | J46: Priority updated.; priority=Critical | K46: Pass | L46: Same as v1.0 | M46: Pass
A47: TC-46 | B47: TNH-12 | C47: Comments | D47: Add a comment on a ticket | E47: ECP (valid class) | F47: Logged in as Christopher | G47: 1. Open TKT-0004 2. Type comment 3. Post comment | H47: Comment: Checking the Outlook profile now | I47: Comment added and shown with name + role | J47: Comment added. | K47: Pass | L47: Same as v1.0 | M47: Pass
A48: TC-47 | B48: TNH-12 | C48: Comments | D48: Post an empty comment | E48: ECP (invalid class) | F48: Logged in as Christopher | G48: 1. Open TKT-0004 2. Leave comment blank 3. Post | H48: Comment: (spaces only) | I48: Error: Comment cannot be empty | J48: Comment cannot be empty. | K48: Pass | L48: Same as v1.0 | M48: Pass
A49: TC-48 | B49: TNH-13 | C49: Resolve | D49: Resolve with a 9-character note (min - 1) | E49: BVA | F49: TKT-0004 In Progress | G49: 1. Login as Christopher 2. Open TKT-0004 3. Note: 9 chars 4. Mark resolved | H49: Note: Fixed it. | I49: Error: Resolution note must be at least 10 characters | J49: Resolution note must be at least 10 characters. | K49: Pass | L49: Same as v1.0 | M49: Pass
A50: TC-49 | B50: TNH-13 | C50: Resolve | D50: Resolve with a valid note | E50: State transition | F50: TKT-0004 In Progress | G50: 1. Open TKT-0004 2. Enter note 3. Mark resolved | H50: Note: Recreated the Outlook profile | I50: Status Resolved, note shown under Resolution | J50: Ticket moved to Resolved.; status=Resolved | K50: Pass | L50: Same as v1.0 | M50: Pass
...

Sheet White-Box
A1: White-Box Testing (TNH-17): Control Flow Graph, Cyclomatic Complexity, Basis Paths
A3: Function 1: validators.validate_password(password)
A4: N1: if not password:
A5: N2: return 'Password is required.'
A6: N3: if len(password) < 8:
A7: N4: return 'at least 8 characters'
A8: N5: if len(password) > 20:
A9: N6: return 'at most 20 characters'
A10: N7: if no letter in password:
A11: N8: return 'must contain a letter'
A12: N9: if no digit in password:
A13: N10: return 'must contain a number'
... A16: Edges: 1-2, 1-3, 2-12, 3-4, 3-5, 4-12, 5-6, 5-7, 6-12, 7-8, 7-9, 8-12, 9-10, 9-11, 10-12, 11-12
A17: Nodes (N) | B17: 12
A18: Edges (E) | B18: 16
A19: Predicate nodes (P) | B19: 5
A20: V(G) = E - N + 2 | B20: =B18-B17+2 -> 6
A21: V(G) = P + 1 | B21: =B19+1 -> 6
A23: Path | B23: Node sequence | C23: Input | D23: Expected output | E23: Actual output | F23: Status | G23: pytest test
A24: P1 | B24: 1-2-12 | C24: '' (empty) | D24: Password is required. | E24: Password is required. | F24: Pass | G24: test_password_paths[-Password is required.]
A25: P2 | B25: 1-3-4-12 | C25: abc123 | D25: at least 8 characters | E25: at least 8 characters | F25: Pass | G25: test_password_paths[abc123-...]
A26: P3 | B26: 1-3-5-6-12 | C26: a1a1a1a1a1a1a1a1a1a1a1 (22) | D26: at most 20 characters | E26: at most 20 characters | F26: Pass | G26: test_password_paths[a1a1...]
A27: P4 | B27: 1-3-5-7-8-12 | C27: 12345678 | D27: must contain a letter | E27: must contain a letter | F27: Pass | G27: test_password_paths[12345678-...]
A28: P5 | B28: 1-3-5-7-9-10-12 | C28: abcdefgh | D28: must contain a number | E28: must contain a number | F28: Pass | G28: test_password_paths[abcdefgh-...]
A29: P6 | B29: 1-3-5-7-9-11-12 | C29: abcdefg1 | D29: None (valid) | E29: None (valid) | F29: Pass | G29: test_password_paths[abcdefg1-None]
A32: Function 2: workflow.can_change_status(current, new, role, is_owner, is_assignee)
A33: N1: who = TRANSITIONS.get((current, new)); if who is None:
A34: N2: return False
A35: N3: if role == 'admin':
A36: N4: return True
A37: N5: if who == 'staff':
A38: N6: role == 'agent' ? (first half of 'and')
A39: N7: -> no: return False
A40: N8: -> yes: return is_assignee
A41: N9: return is_owner
A42: N10: exit
A43: Edges: 1-2, 1-3, 2-10, 3-4, 3-5, 4-10, 5-6, 5-9, 6-7, 6-8, 7-10, 8-10, 9-10
A44: Nodes (N) | B44: 10
A45: Edges (E) | B45: 13
A46: Predicate nodes (P) | B46: 4
...

Sheet BVA
A1: Boundary Value Analysis (TNH-16)
A3: Field | B3: Rule | C3: Min | D3: Max | E3: Min - 1 | F3: Min | G3: Min + 1 | H3: Max - 1 | I3: Max | J3: Max + 1 | K3: Expected | L3: Covered by
A4: Name (register/profile) | B4: 2 to 50 chars | C4: 2 | D4: 50 | E4: 1 -> reject | F4: 2 -> accept | G4: 3 -> accept | H4: 49 -> accept | I4: 50 -> accept | J4: 51 -> reject | K4: Only lengths 2..50 accepted | L4: TC-04, TC-05, test_name
A5: Password | B5: 8 to 20 chars, 1 letter + 1 digit | C5: 8 | D5: 20 | E5: 7 -> reject | F5: 8 -> accept | G5: 9 -> accept | H5: 19 -> accept | I5: 20 -> accept | J5: 21 -> reject | K5: Only lengths 8..20 accepted | L5: TC-06..TC-09, test_password_length_boundaries
A6: Ticket title | B6: 5 to 100 chars (trimmed) | C6: 5 | D6: 100 | E6: 4 -> reject | F6: 5 -> accept | G6: 6 -> accept | H6: 99 -> accept | I6: 100 -> accept | J6: 101 -> reject | K6: Only lengths 5..100 accepted | L6: TC-26..TC-29, test_title_boundaries
A7: Ticket description | B7: 10 to 1000 chars | C7: 10 | D7: 1000 | E7: 9 -> reject | F7: 10 -> accept | G7: 11 -> accept | H7: 999 -> accept | I7: 1000 -> accept | J7: 1001 -> reject | K7: Only lengths 10..1000 accepted | L7: TC-30, TC-31, test_description_boundaries
A8: Resolution note | B8: min 10 chars | C8: 10 | D8: - | E8: 9 -> reject | F8: 10 -> accept | G8: 11 -> accept | H8: - | I8: - | J8: - | K8: Below 10 rejected | L8: TC-48, TC-49, test_resolution_note
A9: Department | B9: max 50 chars (added in v1.1) | C9: 0 | D9: 50 | E9: - | F9: 0 -> accept (optional) | G9: 1 -> accept | H9: 49 -> accept | I9: 50 -> accept | J9: 51 -> reject | K9: Above 50 rejected | L9: TC-24, test_bug04_department_max_50
A10: Comment | B10: 1 to 500 chars | C10: 1 | D10: 500 | E10: 0 -> reject | F10: 1 -> accept | G10: 2 -> accept | H10: 499 -> accept | I10: 500 -> accept | J10: 501 -> reject | K10: Only lengths 1..500 accepted | L10: TC-47, test_comment

Sheet ECP
A1: Equivalence Class Partitioning (TNH-16)
A3: Field | B3: Class ID | C3: Class | D3: Valid / Invalid | E3: Representative value | F3: Expected | G3: Covered by
A4: Email | B4: E1 | C4: Proper format user@domain.tld | D4: Valid | E4: noah@technova.com | F4: Accepted | G4: TC-01, test_email
A5: Email | B5: E2 | C5: Missing @ | D5: Invalid | E5: riyatechnova.com | F5: Enter a valid email address | G5: TC-11
A6: Email | B6: E3 | C6: Missing domain extension | D6: Invalid | E6: noah@technova | F6: Enter a valid email address | G6: test_email
A7: Email | B7: E4 | C7: Contains space | D7: Invalid | E7: noah @technova.com | F7: Enter a valid email address | G7: test_email
A8: Email | B8: E5 | C8: Empty | D8: Invalid | E8: (blank) | F8: Email is required | G8: TC-12
A9: Email | B9: E6 | C9: Uppercase version of existing email | D9: Valid | E9: NOAH@TECHNOVA.COM | F9: Treated same as lowercase | G9: TC-17
A10: Password | B10: P1 | C10: 8-20 chars with letter + digit | D10: Valid | E10: abcdef12 | F10: Accepted | G10: TC-07
A11: Password | B11: P2 | C11: Digits only | D11: Invalid | E11: 12345678 | F11: Must contain a letter | G11: TC-10
A12: Password | B12: P3 | C12: Letters only | D12: Invalid | E12: abcdefgh | F12: Must contain a number | G12: test_password_paths
A13: Password | B13: P4 | C13: Too short / too long | D13: Invalid | E13: abc123 / 22 chars | F13: Length error | G13: TC-06, TC-09
A14: Name | B14: N1 | C14: Letters, space . ' - | D14: Valid | E14: O'Brien | F14: Accepted | G14: test_name
... A26: User role | B26: U3 | C26: Admin | D26: - | E26: admin@technova.com | F26: Sees all, can assign | G26: TC-35, TC-41

Sheet Bug Report
A1: Bug ID | B1: Jira key (log as) | C1: Summary | D1: Story / Module | E1: Severity | F1: Priority | G1: Steps to reproduce | H1: Expected | I1: Actual | J1: Found by | K1: Found in | L1: Fix | M1: Fixed in | N1: Status | O1: Retest
A2: BUG-01 | B2: TNH-20 (Bug) | C2: Search with % or _ returns every ticket | D2: TNH-11 Search | E2: Low | F2: Low | G2: 1. Login as admin 2. Tickets page 3. Type % in search 4. Apply | H2: 0 tickets (no title has %) | I2: All 7 tickets listed | J2: TC-38 | K2: v1.0 | L2: Escaped % and _ in the LIKE pattern (ESCAPE '\') | M2: v1.1 | N2: Closed | O2: Pass (TC-38, test_bug01)
A3: BUG-02 | B3: TNH-21 (Bug) | C3: Searching a number ignores the ticket description | D3: TNH-11 Search | E3: Medium | F3: Medium | G3: 1. Create ticket with 'error 404' in description 2. Search 404 | H3: That ticket is found | I3: 0 tickets found | J3: TC-39 | K3: v1.0 | L3: Numeric search now checks id OR title OR description | M3: v1.1 | N3: Closed | O3: Pass (TC-39, test_bug02)
A4: BUG-03 | B4: TNH-22 (Bug) | C4: Reopened ticket still shows the old resolution note | D4: TNH-13 Resolve & Close | E4: Medium | F4: High | G4: 1. Login as Noah 2. Open resolved TKT-0003 3. Click Reopen ticket | H4: Old fix is cleared while ticket is being worked on again | I4: Status In Progress but 'Resolution: Access granted by IT admin.' still shown | J4: TC-50 | K4: v1.0 | L4: Reopen sets resolution_note to NULL (history stays in Activity) | M4: v1.1 | N4: Closed | O4: Pass (TC-50, test_bug03)
A5: BUG-04 | B5: TNH-23 (Bug) | C5: Department field has no length limit | D5: TNH-7 Profile / TNH-5 Register | E5: Low | F5: Low | G5: 1. Open Profile 2. Paste 5000 characters in Department 3. Save | H5: Error: Department must be at most 50 characters | I5: Profile updated, 5000 chars saved | J5: TC-24 | K5: v1.0 | L5: Added validate_department (max 50) on register + profile | M5: v1.1 | N5: Closed | O5: Pass (TC-24, test_bug04)

Sheet Automated Tests
A1: File | B1: Test | C1: Type | D1: Jira subtask | E1: Result
A2: tests/test_app.py | B2: TestRegisterLogin::test_register_then_login | C2: Integration | D2: TNH-18 | E2: Pass
A3: tests/test_app.py | B3: TestRegisterLogin::test_register_duplicate_email | C3: Integration | D3: TNH-18 | E3: Pass
A4: tests/test_app.py | B4: TestRegisterLogin::test_register_password_mismatch | C4: Integration | D4: TNH-18 | E4: Pass
A5: tests/test_app.py | B5: TestRegisterLogin::test_register_invalid_inputs | C5: Integration | D5: TNH-18 | E5: Pass
A6: tests/test_app.py | B6: TestRegisterLogin::test_login_wrong_password | C6: Integration | D6: TNH-18 | E6: Pass
A7: tests/test_app.py | B7: TestRegisterLogin::test_login_unknown_email | C7: Integration | D7: TNH-18 | E7: Pass
A8: tests/test_app.py | B8: TestRegisterLogin::test_login_empty_fields | C8: Integration | D8: TNH-18 | E8: Pass
A9: tests/test_app.py | B9: TestRegisterLogin::test_protected_page_redirects_to_login | C9: Integration | D9: TNH-18 | E9: Pass
A10: tests/test_app.py | B10: TestRegisterLogin::test_login_redirects_back_to_next | C10: Integration | D10: TNH-18 | E10: Pass
A11: tests/test_app.py | B11: TestRegisterLogin::test_login_ignores_external_next | C11: Integration | D11: TNH-18 | E11: Pass
A12: tests/test_app.py | B12: TestProfileLogout::test_logout_clears_session | C12: Integration | D12: TNH-18 | E12: Pass
... A121: tests/test_workflow.py | B121: test_can_assign[employee-Open-False] | C121: Unit (white-box) | D121: TNH-17 | E121: Pass
